<?xml version="1.0"?>

<robot xmlns:xacro="http://www.ros.org/wiki/xacro">

  <xacro:property name="M_PI" value="1.57079632" />

  <xacro:include filename="$(find hector_xacro_tools)/urdf/inertia_tensors.urdf.xacro" />

  <xacro:macro name="gimbal_macro" params="parent name *origin">

    <joint name="${name}_gimbal_root_joint" type="fixed">
      <xacro:insert_block name="origin"/>
      <axis xyz="0 1 0"/>
      <parent link="${parent}"/>
      <child link="${name}_gimbal_root_link"/>
    </joint>
    
    <link name="${name}_gimbal_root_link">
      <xacro:inertial_sphere_with_pose mass="0.01" diameter="0.03">
        <origin xyz="0.0 0.0 0.0" rpy="0 0 ${M_PI}"/>
      </xacro:inertial_sphere_with_pose>
    </link>

    <link name="${name}_gimbal_pan_link">
      <xacro:inertial_sphere_with_pose mass="0.01" diameter="0.01">
        <origin xyz="0 0 0" rpy="0 0 0"/>
      </xacro:inertial_sphere_with_pose>
    </link>

    <joint name="${name}_gimbal_pan_joint" type="revolute">
      <pose>0 0 0 0 0 0</pose>
      <axis xyz="0 0 1" />
      <parent link="${name}_gimbal_root_link"/>
      <child link="${name}_gimbal_pan_link"/>
      <limit effort="1" velocity="0.5" lower="-${M_PI}" upper="${M_PI}"/>
      <joint_properties damping="2.0" friction="2.0"/>
    </joint>

    <link name="${name}_gimbal_tilt_link">
      <xacro:inertial_sphere_with_pose mass="0.01" diameter="0.01">
        <origin xyz="0 0 0" rpy="0 0 0"/>
      </xacro:inertial_sphere_with_pose>
    </link>

    <joint name="${name}_gimbal_tilt_joint" type="revolute">
      <pose>0 0 0 0 0 0</pose>
      <axis xyz="0 1 0" />
      <parent link="${name}_gimbal_pan_link"/>
      <child link="${name}_gimbal_tilt_link"/>
      <limit effort="1" velocity="0.5" lower="-${M_PI}" upper="${M_PI}"/>
      <joint_properties damping="2.0" friction="2.0"/>
    </joint>

  </xacro:macro>

</robot>
