<?xml version="1.0"?>

<robot xmlns:xacro="http://www.ros.org/wiki/xacro">

  <xacro:include filename="$(find hector_sensors_description)/urdf/sonar_sensor.urdf.xacro" />
  <xacro:property name="pi" value="3.1415926535897931" />

  <!-- Main quadrotor link -->
  <xacro:macro name="bebop2_base_macro">
    <link name="base_link">
      <inertial>
        <mass value="0.503" />
        <origin xyz="0 0 0" />
        <inertia ixx="1.805e-3" ixy="-8.619e-7" ixz="1.555e-5" iyy="1.764e-3" iyz="3.595e-7" izz="3.328e-3" />
      </inertial>

      <visual>
        <origin xyz="0 0 0" rpy="0 0 0" />
        <geometry>
          <mesh filename="package://hector_quadrotor_description/meshes/bebop2/bebop2_hull.dae"/>
        </geometry>
      </visual>

      <collision>
        <origin xyz="0 0 0" rpy="0 0 0" />
        <geometry>
          <mesh filename="package://hector_quadrotor_description/meshes/bebop2/bebop2_hull.dae"/>
        </geometry>
      </collision>
    </link>


    <!-- Sonar height sensor
    <xacro:sonar_sensor name="sonar" parent="base_link" ros_topic="sonar_height" update_rate="10" min_range="0.03" max_range="3.0" field_of_view="${40*pi/180}" ray_count="3">
      <origin xyz="-0.16 0.0 -0.012" rpy="0 ${90*pi/180} 0"/>
    </xacro:sonar_sensor>

<link name="prop_link">


<inertial>
  <mass value="0.0001" />
  <origin xyz="0 0 5" />
  <inertia ixx="0.0001" ixy="0.0001" ixz="0.0001" iyy="0.0001" iyz="0.0001" izz="0.0001" />
</inertial>
  <visual>
    <origin xyz="0 0 5" rpy="0 0 0" />
    <geometry>
      <mesh filename="package://hector_quadrotor_description/meshes/bebop2/bebop2_hull.dae"/>
    </geometry>
  </visual>
</link>

<joint name="prop_joint" type="revolute">
  <axis xyz="0 0 1"/>
  <limit effort="1000.0" lower="0.0" upper="0.548" velocity="0.5"/>
  <origin rpy="0 0 0" xyz="0.2 0.01 0"/>
  <parent link="base_link"/>
  <child link="prop_link"/>
</joint>
-->

<joint name="prop1_joint" type="continuous">
<origin xyz="-0.09035 -0.11423 -0.00501" rpy="0 0 0"/>
<limit effort="1000.0" lower="-2" upper="2" velocity="10"/>
  <axis xyz="0 0 1"/>
  <parent link="base_link"/>
  <child link="prop1"/>
</joint>

<link name="prop1" >
<inertial>
  <mass value="0.0001" />
  <inertia ixx="0.0000001" ixy="0" ixz="0" iyy="0.0000001" iyz="0" izz="0.0000005" />
</inertial>
<visual>
  <geometry>
    <mesh filename="package://hector_quadrotor_description/meshes/bebop2/propeller_rl.dae"/>
  </geometry>
</visual>
</link>

<joint name="prop2_joint" type="continuous">
<origin xyz="-0.09035 0.11452 -0.00501" rpy="0 0 0"/>
<limit effort="1000.0" lower="-2" upper="2" velocity="15"/>
  <axis xyz="0 0 1"/>
  <parent link="base_link"/>
  <child link="prop2"/>
</joint>

<link name="prop2" >
<inertial>
  <mass value="0.0001" />
  <inertia ixx="0.0000001" ixy="0" ixz="0" iyy="0.0000001" iyz="0" izz="0.0000005" />
</inertial>
<visual>
  <geometry>
    <mesh filename="package://hector_quadrotor_description/meshes/bebop2/propeller_rr.dae"/>
  </geometry>
</visual>
</link>

<joint name="prop3_joint" type="continuous">
<origin xyz="0.08456 -0.11435 -0.00501" rpy="0 0 0"/>
<limit effort="1000.0" lower="-2" upper="2" velocity="15"/>
<axis xyz="0 0 1"/>
  <parent link="base_link"/>
  <child link="prop3"/>
</joint>

<link name="prop3" >
<inertial>
  <mass value="0.0001" />
  <inertia ixx="0.0000001" ixy="0" ixz="0" iyy="0.0000001" iyz="0" izz="0.0000005" />
</inertial>
<visual>
  <geometry>
    <mesh filename="package://hector_quadrotor_description/meshes/bebop2/propeller_fl.dae"/>
  </geometry>
</visual>
</link>

<joint name="prop4_joint" type="continuous">
<origin xyz="0.08456 0.11463 -0.00501" rpy="0 0 0"/>
<limit effort="1000.0" lower="-2" upper="2" velocity="15"/>
  <axis xyz="0 0 1"/>
  <parent link="base_link"/>
  <child link="prop4"/>
</joint>

<link name="prop4" >
<inertial>
  <mass value="0.0001" />
  <inertia ixx="0.0000001" ixy="0" ixz="0" iyy="0.0000001" iyz="0" izz="0.0000005" />
</inertial>
<visual>
  <geometry>
    <mesh filename="package://hector_quadrotor_description/meshes/bebop2/propeller_fr.dae"/>
  </geometry>
</visual>
</link>


  </xacro:macro>
</robot>
